<?xml version="1.0"?>
<robot xmlns:sensor="http://playerstage.sourceforge.net/gazebo/xmlschema/#sensor"
xmlns:controller="http://playerstage.sourceforge.net/gazebo/xmlschema/#controller"
xmlns:interface="http://playerstage.sourceforge.net/gazebo/xmlschema/#interface"
xmlns:xacro="http://www.ros.org/wiki/xacro">

  <!-- Import all Gazebo-customization elements, including Gazebo colors -->
  <xacro:include filename="$(find ec2_bringup)/description/schunk/schunk_wsg50.gazebo.xacro" />
  <!-- Import Transmissions -->
  <xacro:include filename="$(find ec2_bringup)/description/schunk/schunk_wsg50.transmission.xacro" />

  <xacro:property name="pi" value="3.1415926535897931" />
  <xacro:property name="jaw_min_position" value="0.0035"/>
  <xacro:property name="jaw_min_position_showcase" value="0.01"/>
   
  <xacro:property name="jaw_max_position" value="0.054"/>
  <xacro:property name="jaw_max_force" value="59.9"/>
  <xacro:property name="jaw_max_velocity" value="0.022"/>
  <xacro:property name="scale" value="0.01"/>

  <xacro:property name="wsg50_base_link_height" value="0.0725"/>

  <xacro:macro name="schunk_wsg50_jaw_visual" params="index">
      <visual>
        <geometry>
            <mesh filename="package://ec2_bringup/meshes/schunk/schunk_wsg50_jaw/schunk_wsg50_jaw_${index}.stl" />
        </geometry>
        <material name="Grey"/>
      </visual>
  </xacro:macro>
  
    <xacro:macro name="schunk_wsg50_jaw_visual1" params="side" >
      <visual>
        <geometry>
            <mesh filename="package://ec2_bringup/meshes/schunk/schunk_wsg50_jaw/gripper_${side}_noFinger.stl" scale="${scale} ${scale} ${scale}" />
        </geometry>
        <origin xyz="0 0 0" rpy="0 0 0"/>        
        <material name="Grey"/>
      </visual>
  </xacro:macro>


  <xacro:macro name="schunk_wsg50_jaw_collision" params="index">
      <collision>
        <geometry>
            <mesh filename="package://ec2_bringup/meshes/schunk/schunk_wsg50_jaw/schunk_wsg50_jaw_${index}.stl" />
        </geometry>
        <material name="Grey"/>
      </collision>
  </xacro:macro>
  
  <xacro:macro name="schunk_wsg50_jaw_collision1" params="side">
      <collision>
        <geometry>
            <mesh filename="package://ec2_bringup/meshes/schunk/schunk_wsg50_jaw/gripper_${side}_noFinger.stl" scale="${scale} ${scale} ${scale}" />
        </geometry>
        <origin xyz="0 0 0" rpy="0 0 0"/>        
        <material name="Grey"/>
      </collision>
  </xacro:macro>
  

  <xacro:macro name="schunk_wsg50_jaw_collision_tip">
      <collision>
        <geometry>
          <box size="0.04 0.020 0.012"/>
        </geometry>
        <origin xyz="0.006 0 0.061" rpy="0 ${pi/2} 0"/>
        <surface>
            <friction>
              <bullet>
                <rolling_friction>1</rolling_friction>
                <friction>2</friction>
              </bullet>
              <ode/>
            </friction>
            <bounce/>
            <contact>
              <ode/>
            </contact>
          </surface>
      </collision>
  </xacro:macro>
  
  <xacro:macro name="schunk_wsg50_jaw_collision_tip_small" params="colision_name">
      <collision name="${colision_name}">
        <geometry>
            <cylinder radius="0.01" length="0.008">
          </cylinder>
        </geometry>
        <origin xyz="0.001 0 0.071" rpy="0 ${pi/2} 0"/>
          <surface>
          <friction>
            <bullet>
              <surface_material_name>gripper_finger_rubber</surface_material_name>
            </bullet>
          </friction>
        </surface>
          <max_contacts>2</max_contacts>
      </collision>
  </xacro:macro>

  <xacro:macro name="schunk_wsg50_jaw" params="link_name side" >
    <link name="${link_name}">
        <xacro:schunk_wsg50_jaw_visual index="1" />
        <xacro:if value="${showcase}">
          <xacro:schunk_wsg50_jaw_visual1 side="${side}"/>
          <xacro:schunk_wsg50_jaw_collision1 side="${side}"/>  
        </xacro:if>
        <xacro:unless value="${showcase}">
          <xacro:schunk_wsg50_jaw_visual index="2" />
          <xacro:schunk_wsg50_jaw_visual index="3" />
        </xacro:unless>
        <!--<xacro:schunk_wsg50_jaw_collision index="1" />        
        <xacro:schunk_wsg50_jaw_collision index="2" /> -->
        
        
        <xacro:unless value="${showcase}">
<!--
          <xacro:schunk_wsg50_jaw_collision_tip/>
-->
        </xacro:unless>
        <inertial>
        <!-- Estimated from reference sheet -->
          <mass value="0.05" />
          <inertia ixx="0.0000577" ixy="0" ixz="0" iyy="0.000061" iyz="0" izz="0.0000274"/>
        </inertial>
      <gravity>1</gravity>
      <gazebo>
      	<selfCollide>false</selfCollide>
      	<self_collide>false</self_collide>
      </gazebo>
    </link>
    
    <xacro:if value="${showcase}">
    	<link name="${link_name}_finger">
    	   <visual>
        	  <geometry>
           		<mesh filename="package://ec2_bringup/meshes/schunk/schunk_wsg50_jaw/finger.stl" scale="${scale} ${scale} ${scale}" />
        	  </geometry>
        	  <origin xyz="0 0 0" rpy="0 0 0"/>        
        	  <material name="Grey"/>
      	  	</visual>
      	  	<collision>
        	  <geometry>
            	<mesh filename="package://ec2_bringup/meshes/schunk/schunk_wsg50_jaw/finger.stl" scale="${scale} ${scale} ${scale}" />
        	  </geometry>
        	  <origin xyz="0 0 0" rpy="0 0 0"/>        
         	  <material name="Grey"/>
      		</collision>
    	</link>
    </xacro:if>
    <xacro:unless value="${showcase}">
    <link name="${link_name}_tip">
        <xacro:schunk_wsg50_jaw_collision_tip_small colision_name="${link_name}_finger_tip_colision"/>
        <inertial>
        <!-- Estimated from reference sheet -->
          <mass value="0.005" />
          <inertia ixx="0.0000577" ixy="0" ixz="0" iyy="0.000061" iyz="0" izz="0.0000274"/>
        </inertial>
    </link>
    </xacro:unless>
    
  </xacro:macro>

  <xacro:macro name="schunk_wsg50" params="parent_link name hardware_interface *origin">
    <joint name="${name}_fixed_base_joint" type="fixed">
       <xacro:insert_block name="origin"/>
       <child link="${name}_link_base" />
       <parent link="${parent_link}"/>
    </joint>

    <link name="${name}_link_base">
      <visual>
        <geometry>
            <mesh filename="package://ec2_bringup/meshes/schunk/schunk_wsg50_base/schung_wsg50_base.stl" />
        </geometry>
        <material name="Light Grey"/>
      </visual>
      <collision>
        <geometry>
            <mesh filename="package://ec2_bringup/meshes/schunk/schunk_wsg50_base/schung_wsg50_base.stl" />
        </geometry>
        <material name="Light Grey"/>
      </collision>
      <inertial>
        <!-- Estimated from reference sheet -->
        <mass value="0.1" />
        <inertia
         ixx="1.0" ixy="0.0" ixz="0.0"
         iyy="1.0" iyz="0.0"
         izz="1.0" />
      </inertial>
    </link>

    <joint name="${name}_joint_right_jaw" type="prismatic">
       <origin xyz="0 0 ${wsg50_base_link_height}" rpy="0 0 0" />
       <axis xyz="1 0 0"/>
       <xacro:if value="${showcase}">
         <limit lower="${jaw_min_position_showcase}" upper="${jaw_max_position}" effort="${jaw_max_force}" velocity="${jaw_max_velocity}"/>
       </xacro:if>
       <xacro:unless value="${showcase}">
         <limit lower="${jaw_min_position}" upper="${jaw_max_position}" effort="${jaw_max_force}" velocity="${jaw_max_velocity}"/>
       </xacro:unless>
       <parent link="${name}_link_base"/>
       <child link="${name}_link_right_jaw" />
    </joint>
    
    <xacro:schunk_wsg50_jaw link_name="${name}_link_right_jaw" side="1"/>
    
    <xacro:if value="${showcase}">
    <joint name="${name}_joint_right_jaw_finger" type="fixed">
       <origin xyz="0.06 0.010 0.117" rpy="0 0 0" />
       <parent link="${name}_link_right_jaw"/>
       <child link="${name}_link_right_jaw_finger" />
    </joint>
	</xacro:if>
    <xacro:unless value="${showcase}">
    <joint name="${name}_joint_right_jaw_tip" type="fixed">
       <origin xyz="0 0 0" rpy="0 0 0" />
       <parent link="${name}_link_right_jaw"/>
       <child link="${name}_link_right_jaw_tip" />
    </joint>
	</xacro:unless>

    <joint name="${name}_joint_left_jaw" type="prismatic">
       <origin xyz="0 0 ${wsg50_base_link_height}" rpy="0 0 ${pi}" />
       <axis xyz="1 0 0"/>
       <xacro:if value="${showcase}">
         <limit lower="${jaw_min_position_showcase}" upper="${jaw_max_position}" effort="${jaw_max_force}" velocity="${jaw_max_velocity}"/>
       </xacro:if>
       <xacro:unless value="${showcase}">
         <limit lower="${jaw_min_position}" upper="${jaw_max_position}" effort="${jaw_max_force}" velocity="${jaw_max_velocity}"/>
       </xacro:unless>
       <mimic joint="${name}_joint_right_jaw" multiplier="-1"/>
       <parent link="${name}_link_base"/>
       <child link="${name}_link_left_jaw" />
    </joint>

    <xacro:schunk_wsg50_jaw link_name="${name}_link_left_jaw" side="2"/>
    
    <xacro:if value="${showcase}">
    <joint name="${name}_joint_left_jaw_finger" type="fixed">
       <origin xyz="0.06 -0.010 0.117" rpy="0 0 0" />
       <parent link="${name}_link_left_jaw"/>
       <child link="${name}_link_left_jaw_finger" />
    </joint>
    </xacro:if>    
    <xacro:unless value="${showcase}">
    <joint name="${name}_joint_left_jaw_tip" type="fixed">
       <origin xyz="0 0 0" rpy="0 0 0" />
       <parent link="${name}_link_left_jaw"/>
       <child link="${name}_link_left_jaw_tip" />
    </joint>
    </xacro:unless>

    <joint name="${name}_palm_joint" type="fixed">
       <origin xyz="0.0 0.0 ${wsg50_base_link_height}" rpy="0 0 0"/>
       <parent link="${name}_link_base"/>
       <child link="${name}_link_palm" />
    </joint>

    <link name="${name}_link_palm"/>

    <!--Extensions -->
    <xacro:schunk_wsg50_gazebo name="${name}" />
    <xacro:schunk_wsg50_transmission name="${name}" hardware_interface="${hardware_interface}"/>

  </xacro:macro>

<gazebo>
   <plugin name="gazebo_grasp_fix" filename="libgazebo_grasp_fix.so">
        <arm>
           <arm_name>schunk_wsg50</arm_name>
               	<gripper_link> schunk_wsg50_link_left_jaw </gripper_link>
    			<gripper_link> schunk_wsg50_link_right_jaw </gripper_link>
    			<palm_link> lbr_iiwa_link_7 </palm_link>
        </arm>
       <forces_angle_tolerance>90</forces_angle_tolerance>
       <update_rate>10</update_rate>
       <grip_count_threshold>2</grip_count_threshold>
       <max_grip_count>4</max_grip_count>
       <release_tolerance>0.002</release_tolerance>
       <disable_collisions_on_attach>true</disable_collisions_on_attach>
       <contact_topic>__default_topic__</contact_topic>
    </plugin>
</gazebo>

</robot>

